schematic = {
	size = {x=7, y=7, z=1},
	yslice_prob = {
		{ypos=0, prob=254},
		{ypos=1, prob=254},
		{ypos=2, prob=254},
		{ypos=3, prob=254},
		{ypos=4, prob=254},
		{ypos=5, prob=254},
		{ypos=6, prob=254},
	},
	data = {
		{name="air", prob=0, param2=0},
		{name="air", prob=0, param2=0},
		{name="air", prob=0, param2=0},
		{name="x_farming:cactus", prob=254, param2=20, force_place=true},
		{name="air", prob=0, param2=0},
		{name="air", prob=0, param2=0},
		{name="air", prob=0, param2=0},
		{name="air", prob=0, param2=0},
		{name="air", prob=0, param2=0},
		{name="air", prob=0, param2=0},
		{name="x_farming:cactus", prob=254, param2=20},
		{name="air", prob=0, param2=0},
		{name="air", prob=0, param2=0},
		{name="air", prob=0, param2=0},
		{name="x_farming:cactus", prob=254, param2=20},
		{name="x_farming:cactus", prob=254, param2=20},
		{name="x_farming:cactus", prob=254, param2=20},
		{name="x_farming:cactus", prob=254, param2=20},
		{name="x_farming:cactus", prob=254, param2=20},
		{name="x_farming:cactus", prob=254, param2=20},
		{name="x_farming:cactus", prob=254, param2=20},
		{name="x_farming:cactus", prob=254, param2=20},
		{name="x_farming:cactus_fruit", prob=170, param2=20},
		{name="x_farming:cactus_fruit", prob=170, param2=20},
		{name="x_farming:cactus", prob=254, param2=20},
		{name="x_farming:cactus_fruit", prob=170, param2=20},
		{name="x_farming:cactus_fruit", prob=170, param2=20},
		{name="x_farming:cactus", prob=254, param2=20},
		{name="x_farming:cactus", prob=126, param2=20},
		{name="air", prob=0, param2=0},
		{name="air", prob=0, param2=0},
		{name="x_farming:cactus", prob=254, param2=20},
		{name="air", prob=0, param2=0},
		{name="air", prob=0, param2=0},
		{name="x_farming:cactus", prob=126, param2=20},
		{name="air", prob=0, param2=0},
		{name="air", prob=0, param2=0},
		{name="air", prob=0, param2=0},
		{name="x_farming:cactus", prob=254, param2=20},
		{name="air", prob=0, param2=0},
		{name="air", prob=0, param2=0},
		{name="air", prob=0, param2=0},
		{name="air", prob=0, param2=0},
		{name="air", prob=0, param2=0},
		{name="air", prob=0, param2=0},
		{name="x_farming:cactus_fruit", prob=170, param2=20},
		{name="air", prob=0, param2=0},
		{name="air", prob=0, param2=0},
		{name="air", prob=0, param2=0},
	},
}
