schematic = {
	size = {x=3, y=8, z=3},
	yslice_prob = {
		{ypos=0, prob=254},
		{ypos=1, prob=254},
		{ypos=2, prob=254},
		{ypos=3, prob=254},
		{ypos=4, prob=254},
		{ypos=5, prob=254},
		{ypos=6, prob=254},
		{ypos=7, prob=254},
	},
	data = {
		{name="air", prob=254, param2=0},
		{name="air", prob=254, param2=0},
		{name="air", prob=254, param2=0},
		{name="x_farming:christmas_tree_leaves", prob=254, param2=0},
		{name="x_farming:christmas_tree_leaves", prob=254, param2=0},
		{name="x_farming:christmas_tree_leaves", prob=254, param2=0},
		{name="x_farming:christmas_tree_leaves", prob=254, param2=0},
		{name="x_farming:christmas_tree_leaves", prob=254, param2=0},
		{name="x_farming:christmas_tree_leaves", prob=254, param2=0},
		{name="air", prob=254, param2=0},
		{name="x_farming:christmas_tree_leaves", prob=254, param2=0},
		{name="air", prob=254, param2=0},
		{name="air", prob=254, param2=0},
		{name="x_farming:christmas_tree_leaves", prob=254, param2=0},
		{name="air", prob=254, param2=0},
		{name="air", prob=254, param2=0},
		{name="air", prob=254, param2=0},
		{name="air", prob=254, param2=0},
		{name="air", prob=254, param2=0},
		{name="air", prob=254, param2=0},
		{name="air", prob=254, param2=0},
		{name="air", prob=254, param2=0},
		{name="air", prob=254, param2=0},
		{name="air", prob=254, param2=0},
		{name="air", prob=254, param2=0},
		{name="x_farming:pine_nut_tree", prob=254, param2=0, force_place=true},
		{name="air", prob=254, param2=0},
		{name="x_farming:christmas_tree_leaves", prob=254, param2=0},
		{name="x_farming:pine_nut_tree", prob=254, param2=0},
		{name="x_farming:christmas_tree_leaves", prob=254, param2=0},
		{name="x_farming:christmas_tree_leaves", prob=254, param2=0},
		{name="x_farming:pine_nut_tree", prob=254, param2=0},
		{name="x_farming:christmas_tree_leaves", prob=254, param2=0},
		{name="x_farming:christmas_tree_leaves", prob=254, param2=0},
		{name="x_farming:pine_nut_tree", prob=254, param2=0},
		{name="x_farming:christmas_tree_leaves", prob=254, param2=0},
		{name="x_farming:christmas_tree_leaves", prob=254, param2=0},
		{name="x_farming:pine_nut_tree", prob=254, param2=0},
		{name="x_farming:christmas_tree_leaves", prob=254, param2=0},
		{name="air", prob=254, param2=0},
		{name="x_farming:christmas_tree_leaves", prob=254, param2=0},
		{name="air", prob=254, param2=0},
		{name="air", prob=254, param2=0},
		{name="x_farming:christmas_tree_leaves", prob=254, param2=0},
		{name="air", prob=254, param2=0},
		{name="air", prob=254, param2=0},
		{name="x_farming:christmas_tree_star", prob=126, param2=0},
		{name="air", prob=254, param2=0},
		{name="air", prob=254, param2=0},
		{name="air", prob=254, param2=0},
		{name="air", prob=254, param2=0},
		{name="x_farming:christmas_tree_leaves", prob=254, param2=0},
		{name="x_farming:christmas_tree_leaves", prob=254, param2=0},
		{name="x_farming:christmas_tree_leaves", prob=254, param2=0},
		{name="x_farming:christmas_tree_leaves", prob=254, param2=0},
		{name="x_farming:christmas_tree_leaves", prob=254, param2=0},
		{name="x_farming:christmas_tree_leaves", prob=254, param2=0},
		{name="air", prob=254, param2=0},
		{name="x_farming:christmas_tree_leaves", prob=254, param2=0},
		{name="air", prob=254, param2=0},
		{name="air", prob=254, param2=0},
		{name="x_farming:christmas_tree_leaves", prob=254, param2=0},
		{name="air", prob=254, param2=0},
		{name="air", prob=254, param2=0},
		{name="air", prob=254, param2=0},
		{name="air", prob=254, param2=0},
		{name="air", prob=254, param2=0},
		{name="air", prob=254, param2=0},
		{name="air", prob=254, param2=0},
		{name="air", prob=254, param2=0},
		{name="air", prob=254, param2=0},
		{name="air", prob=254, param2=0},
	},
}
